<?xml version="1.0"?>
<robot xmlns:xacro="http://www.ros.org/wiki/xacro">

   <xacro:include filename="inertial_macros.xacro"/>

    <material name="white">
        <color rgba="1 1 1 1"/>
    </material>

    <material name="orange">
        <color rgba="1 0.3 0.1 1"/>
    </material>

    <material name="blue">
        <color rgba="0.2 0.2 1 1"/>
    </material>

    <material name="black">
        <color rgba="0 0 0 1"/>
    </material>

    <material name="red">
        <color rgba="1 0 0 1"/>
    </material>
    
    <material name="green">
        <color rgba="0.2 1 0.4 1"/>
    </material>
    
    <link name="base_link">

    </link>

     <!-- BASE_FOOTPRINT LINK -->

     <joint name="base_footprint_joint" type="fixed">
        <parent link="base_link"/>
        <child link="base_footprint"/>
        <origin xyz="0 0 0" rpy="0 0 0"/>
    </joint>

    <link name="base_footprint">
    </link>

<!-- Chassis -->


    <joint name="chassis_joint" type="fixed">

        <parent link="base_link"/>
        <child link="chassis"/>
        <origin xyz="-0.01 0 0"/>

    </joint>

    

    <link name="chassis">
        <visual>
            <origin xyz="0.065 0 0.02"/>
            <geometry>
                <box size="0.13 0.12 0.07"/>
            </geometry>
            <material name="black"/>
        </visual>
        <collision>
            <origin xyz="0.065 0 0.02" rpy="0 0 0"/>
            <geometry>
                <box size="0.13 0.12 0.07"/>
            </geometry>
        </collision>

        <xacro:inertial_box mass="0.5" x="0.13" y="0.12" z="0.07">
           <origin xyz="0.065 0 0.02" rpy="0 0 0"/>
       </xacro:inertial_box>

    </link>
    <gazebo reference="chassis">
        <material>Gazebo/Black</material>

    </gazebo>

<!-- Left Wheel -->


    <joint name="left_wheel_joint" type="continuous">

        <parent link="base_link"/>
        <child link="left_wheel"/>
        <origin xyz="0 0.085 0" rpy="-${pi/2} 0 0"/>
        <axis xyz="0 0 1"/>

    </joint>

    <link name="left_wheel">

        <visual>
            <geometry>
                <cylinder length="0.02" radius="0.025"/>
            </geometry>

            <material name="green"/>
        </visual>
        <collision>
            <geometry>
                <sphere  radius="0.025"/>
            </geometry>
        </collision>

        <xacro:inertial_cylinder mass="0.1" length="0.02" radius="0.025">
            <origin xyz="0 0 0" rpy="0 0 0"/>
        </xacro:inertial_cylinder>
    </link>
   
    <gazebo reference="left_wheel">
        <material>Gazebo/Green</material>

    </gazebo>

<!-- Right Wheel -->
     <joint name="right_wheel_joint" type="continuous">

        <parent link="base_link"/>
        <child link="right_wheel"/>
        <origin xyz="0 -0.085 0" rpy="${pi/2} 0 0"/>
        <axis xyz="0 0 -1"/>

    </joint>

    <link name="right_wheel">

        <visual>

            <geometry>
                <cylinder length="0.02" radius="0.025"/>
            </geometry>

            <material name="green"/>

        </visual>
        <collision>

            <geometry>
                <sphere  radius="0.025"/>
            </geometry>
        </collision>   

        <xacro:inertial_cylinder mass="0.1" length="0.02" radius="0.025">
            <origin xyz="0 0 0" rpy="0 0 0"/>
        </xacro:inertial_cylinder>

    </link>

    <gazebo reference="right_wheel">
        <material>Gazebo/Green</material>

    </gazebo>

<!-- CASTER WHEEL -->

<joint name="left_caster_wheel_joint" type="fixed">

    <parent link="base_link"/>
    <child link="left_caster_wheel"/>
    <origin xyz="0.11 0.085 0" rpy="-${pi/2} 0 0"/>
    <axis xyz="0 0 1"/>

</joint>

<link name="left_caster_wheel">

    <visual>
        <geometry>
            <cylinder length="0.02" radius="0.025"/>
        </geometry>

        <material name="green"/>
    </visual>
    <collision>
        <geometry>
            <sphere  radius="0.025"/>
        </geometry>
    </collision>

    <xacro:inertial_cylinder mass="0.1" length="0.02" radius="0.025">
        <origin xyz="0 0 0" rpy="0 0 0"/>
    </xacro:inertial_cylinder>
</link>

<gazebo reference="left_caster_wheel">
    <material>Gazebo/Green</material>
    <mu1 value="0.001"/>
    <mu2 value="0.001"/>

</gazebo>


<joint name="right_caster_wheel_joint" type="fixed">

    <parent link="base_link"/>
    <child link="right_caster_wheel"/>
    <origin xyz="0.11 -0.085 0" rpy="${pi/2} 0 0"/>
    <axis xyz="0 0 -1"/>

</joint>

<link name="right_caster_wheel">

    <visual>

        <geometry>
            <cylinder length="0.02" radius="0.025"/>
        </geometry>

        <material name="green"/>

    </visual>
    <collision>

        <geometry>
            <sphere  radius="0.025"/>
        </geometry>
    </collision>   

    <xacro:inertial_cylinder mass="0.1" length="0.02" radius="0.025">
        <origin xyz="0 0 0" rpy="0 0 0"/>
    </xacro:inertial_cylinder>

</link>

<gazebo reference="right_caster_wheel">
    <material>Gazebo/Green</material>
    <mu1 value="0.001"/>
    <mu2 value="0.001"/>
</gazebo>





</robot>